ProgrammingError
sqlalchemy.exc.ProgrammingError: (psycopg2.errors.UndefinedColumn) column user_settings.user_id does not exist
LINE 1: SELECT user_settings.id AS user_settings_id, user_settings.u...
                                                     ^

[SQL: SELECT user_settings.id AS user_settings_id, user_settings.user_id AS user_settings_user_id, user_settings.session_id AS user_settings_session_id, user_settings.threshold AS user_settings_threshold, user_settings.sort_by AS user_settings_sort_by, user_settings.sort_order AS user_settings_sort_order, user_settings.sector_filter AS user_settings_sector_filter, user_settings.selected_tickers AS user_settings_selected_tickers, user_settings.created_at AS user_settings_created_at, user_settings.updated_at AS user_settings_updated_at 
FROM user_settings 
WHERE user_settings.session_id = %(session_id_1)s 
 LIMIT %(param_1)s]
[parameters: {'session_id_1': 'a06fc74c-dab6-4644-a4c5-7deea01b3da7', 'param_1': 1}]
(Background on this error at: https://sqlalche.me/e/20/f405)

Traceback (most recent call last)
File "/home/runner/workspace/.pythonlibs/lib/python3.11/site-packages/sqlalchemy/engine/base.py", line 1961, in _exec_single_context
self.dialect.do_execute(
^
File "/home/runner/workspace/.pythonlibs/lib/python3.11/site-packages/sqlalchemy/engine/default.py", line 944, in do_execute
cursor.execute(statement, parameters)
^^^^^^^^^^^^^^^^^^^^^^^^^^^^^^^^^^^^^
The above exception was the direct cause of the following exception:
File "/home/runner/workspace/.pythonlibs/lib/python3.11/site-packages/flask/app.py", line 1536, in __call__
return self.wsgi_app(environ, start_response)
       ^^^^^^^^^^^^^^^^^^^^^^^^^^^^^^^^^^^^^^
File "/home/runner/workspace/.pythonlibs/lib/python3.11/site-packages/flask/app.py", line 1514, in wsgi_app
response = self.handle_exception(e)
           ^^^^^^^^^^^^^^^^^^^^^^^^
File "/home/runner/workspace/.pythonlibs/lib/python3.11/site-packages/flask/app.py", line 1511, in wsgi_app
response = self.full_dispatch_request()
           ^^^^^^^^^^^^^^^^^^^^^^^^^^^^
File "/home/runner/workspace/.pythonlibs/lib/python3.11/site-packages/flask/app.py", line 919, in full_dispatch_request
rv = self.handle_user_exception(e)
     ^^^^^^^^^^^^^^^^^^^^^^^^^^^^^
File "/home/runner/workspace/.pythonlibs/lib/python3.11/site-packages/flask/app.py", line 917, in full_dispatch_request
rv = self.dispatch_request()
     ^^^^^^^^^^^^^^^^^^^^^^^
File "/home/runner/workspace/.pythonlibs/lib/python3.11/site-packages/flask/app.py", line 902, in dispatch_request
return self.ensure_sync(self.view_functions[rule.endpoint])(**view_args)  # type: ignore[no-any-return]
       ^^^^^^^^^^^^^^^^^^^^^^^^^^^^^^^^^^^^^^^^^^^^^^^^^^^^^^^^^^^^^^^^^
File "/home/runner/workspace/app.py", line 215, in analysis
settings = get_user_settings()
           ^^^^^^^^^^^^^^^^^^^
File "/home/runner/workspace/app.py", line 112, in get_user_settings
settings = UserSettings.query.filter_by(session_id=session_id).first()
           ^^^^^^^^^^^^^^^^^^^^^^^^^^^^^^^^^^^^^^^^^^^^^^^^^^^^^^^^^^^
File "/home/runner/workspace/.pythonlibs/lib/python3.11/site-packages/sqlalchemy/orm/query.py", line 2759, in first
return self.limit(1)._iter().first()  # type: ignore
       ^^^^^^^^^^^^^^^^^^^^^
File "/home/runner/workspace/.pythonlibs/lib/python3.11/site-packages/sqlalchemy/orm/query.py", line 2857, in _iter
result: Union[ScalarResult[_T], Result[_T]] = self.session.execute(
                                              
File "/home/runner/workspace/.pythonlibs/lib/python3.11/site-packages/sqlalchemy/orm/session.py", line 2365, in execute
return self._execute_internal(
       
File "/home/runner/workspace/.pythonlibs/lib/python3.11/site-packages/sqlalchemy/orm/session.py", line 2251, in _execute_internal
result: Result[Any] = compile_state_cls.orm_execute_statement(
                      
File "/home/runner/workspace/.pythonlibs/lib/python3.11/site-packages/sqlalchemy/orm/context.py", line 306, in orm_execute_statement
result = conn.execute(
         
File "/home/runner/workspace/.pythonlibs/lib/python3.11/site-packages/sqlalchemy/engine/base.py", line 1413, in execute
return meth(
       
File "/home/runner/workspace/.pythonlibs/lib/python3.11/site-packages/sqlalchemy/sql/elements.py", line 526, in _execute_on_connection
return connection._execute_clauseelement(
       
File "/home/runner/workspace/.pythonlibs/lib/python3.11/site-packages/sqlalchemy/engine/base.py", line 1635, in _execute_clauseelement
ret = self._execute_context(
      
File "/home/runner/workspace/.pythonlibs/lib/python3.11/site-packages/sqlalchemy/engine/base.py", line 1840, in _execute_context
return self._exec_single_context(
       
File "/home/runner/workspace/.pythonlibs/lib/python3.11/site-packages/sqlalchemy/engine/base.py", line 1980, in _exec_single_context
self._handle_dbapi_exception(
^
File "/home/runner/workspace/.pythonlibs/lib/python3.11/site-packages/sqlalchemy/engine/base.py", line 2349, in _handle_dbapi_exception
raise sqlalchemy_exception.with_traceback(exc_info[2]) from e
^^^^^^^^^^^^^^^^^^^^^^^^^^^^^^^^^^^^^^^^^^^^^^^^^^^^^^^^^^^^^
File "/home/runner/workspace/.pythonlibs/lib/python3.11/site-packages/sqlalchemy/engine/base.py", line 1961, in _exec_single_context
self.dialect.do_execute(
^
File "/home/runner/workspace/.pythonlibs/lib/python3.11/site-packages/sqlalchemy/engine/default.py", line 944, in do_execute
cursor.execute(statement, parameters)
^^^^^^^^^^^^^^^^^^^^^^^^^^^^^^^^^^^^^
sqlalchemy.exc.ProgrammingError: (psycopg2.errors.UndefinedColumn) column user_settings.user_id does not exist
LINE 1: SELECT user_settings.id AS user_settings_id, user_settings.u...
^

[SQL: SELECT user_settings.id AS user_settings_id, user_settings.user_id AS user_settings_user_id, user_settings.session_id AS user_settings_session_id, user_settings.threshold AS user_settings_threshold, user_settings.sort_by AS user_settings_sort_by, user_settings.sort_order AS user_settings_sort_order, user_settings.sector_filter AS user_settings_sector_filter, user_settings.selected_tickers AS user_settings_selected_tickers, user_settings.created_at AS user_settings_created_at, user_settings.updated_at AS user_settings_updated_at
FROM user_settings
WHERE user_settings.session_id = %(session_id_1)s
LIMIT %(param_1)s]
[parameters: {'session_id_1': 'a06fc74c-dab6-4644-a4c5-7deea01b3da7', 'param_1': 1}]
(Background on this error at: https://sqlalche.me/e/20/f405)
The debugger caught an exception in your WSGI application. You can now look at the traceback which led to the error.
To switch between the interactive traceback and the plaintext one, you can click on the "Traceback" headline. From the text traceback you can also create a paste of it.

Brought to you by DON'T PANIC, your friendly Werkzeug powered traceback interpreter.